python3: can't open file 'update.py&': [Errno 2] No such file or directory
python3: can't open file 'update.py&': [Errno 2] No such file or directory
Traceback (most recent call last):
  File "update.py", line 33, in <module>
    webServer = HTTPServer(("localhost", 2545), Server)
  File "/usr/lib/python3.8/socketserver.py", line 452, in __init__
    self.server_bind()
  File "/usr/lib/python3.8/http/server.py", line 138, in server_bind
    socketserver.TCPServer.server_bind(self)
  File "/usr/lib/python3.8/socketserver.py", line 466, in server_bind
    self.socket.bind(self.server_address)
OSError: [Errno 98] Address already in use
python3: can't open file 'update.py&': [Errno 2] No such file or directory
python3: can't open file 'update.py&': [Errno 2] No such file or directory
python3: can't open file 'update.py&': [Errno 2] No such file or directory
Traceback (most recent call last):
  File "update.py", line 33, in <module>
    webServer = HTTPServer(("localhost", 2545), Server)
  File "/usr/lib/python3.8/socketserver.py", line 452, in __init__
    self.server_bind()
  File "/usr/lib/python3.8/http/server.py", line 138, in server_bind
    socketserver.TCPServer.server_bind(self)
  File "/usr/lib/python3.8/socketserver.py", line 466, in server_bind
    self.socket.bind(self.server_address)
OSError: [Errno 98] Address already in use
Traceback (most recent call last):
  File "update.py", line 33, in <module>
    webServer = HTTPServer(("localhost", 2545), Server)
  File "/usr/lib/python3.8/socketserver.py", line 452, in __init__
    self.server_bind()
  File "/usr/lib/python3.8/http/server.py", line 138, in server_bind
    socketserver.TCPServer.server_bind(self)
  File "/usr/lib/python3.8/socketserver.py", line 466, in server_bind
    self.socket.bind(self.server_address)
OSError: [Errno 98] Address already in use
Traceback (most recent call last):
  File "update.py", line 33, in <module>
    webServer = HTTPServer(("localhost", 2545), Server)
  File "/usr/lib/python3.8/socketserver.py", line 452, in __init__
    self.server_bind()
  File "/usr/lib/python3.8/http/server.py", line 138, in server_bind
    socketserver.TCPServer.server_bind(self)
  File "/usr/lib/python3.8/socketserver.py", line 466, in server_bind
    self.socket.bind(self.server_address)
OSError: [Errno 98] Address already in use
Traceback (most recent call last):
  File "update.py", line 33, in <module>
    webServer = HTTPServer(("localhost", 2545), Server)
  File "/usr/lib/python3.8/socketserver.py", line 452, in __init__
    self.server_bind()
  File "/usr/lib/python3.8/http/server.py", line 138, in server_bind
    socketserver.TCPServer.server_bind(self)
  File "/usr/lib/python3.8/socketserver.py", line 466, in server_bind
    self.socket.bind(self.server_address)
OSError: [Errno 98] Address already in use
Traceback (most recent call last):
  File "update.py", line 33, in <module>
    webServer = HTTPServer(("localhost", 2545), Server)
  File "/usr/lib/python3.8/socketserver.py", line 452, in __init__
    self.server_bind()
  File "/usr/lib/python3.8/http/server.py", line 138, in server_bind
    socketserver.TCPServer.server_bind(self)
  File "/usr/lib/python3.8/socketserver.py", line 466, in server_bind
    self.socket.bind(self.server_address)
OSError: [Errno 98] Address already in use
Traceback (most recent call last):
  File "update.py", line 33, in <module>
    webServer = HTTPServer(("localhost", 2545), Server)
  File "/usr/lib/python3.8/socketserver.py", line 452, in __init__
    self.server_bind()
  File "/usr/lib/python3.8/http/server.py", line 138, in server_bind
    socketserver.TCPServer.server_bind(self)
  File "/usr/lib/python3.8/socketserver.py", line 466, in server_bind
    self.socket.bind(self.server_address)
OSError: [Errno 98] Address already in use
Traceback (most recent call last):
  File "update.py", line 33, in <module>
    webServer = HTTPServer(("localhost", 2545), Server)
  File "/usr/lib/python3.8/socketserver.py", line 452, in __init__
    self.server_bind()
  File "/usr/lib/python3.8/http/server.py", line 138, in server_bind
    socketserver.TCPServer.server_bind(self)
  File "/usr/lib/python3.8/socketserver.py", line 466, in server_bind
    self.socket.bind(self.server_address)
OSError: [Errno 98] Address already in use
python3: can't open file 'update.py&': [Errno 2] No such file or directory
python3: can't open file 'update.py ': [Errno 2] No such file or directory
python3: can't open file 'update.py ': [Errno 2] No such file or directory
Traceback (most recent call last):
  File "update.py", line 33, in <module>
    webServer = HTTPServer(("localhost", 2545), Server)
  File "/usr/lib/python3.8/socketserver.py", line 452, in __init__
    self.server_bind()
  File "/usr/lib/python3.8/http/server.py", line 138, in server_bind
    socketserver.TCPServer.server_bind(self)
  File "/usr/lib/python3.8/socketserver.py", line 466, in server_bind
    self.socket.bind(self.server_address)
OSError: [Errno 98] Address already in use
python3: can't open file '/Redstoneguy129/update.py': [Errno 2] No such file or directory
python3: can't open file '/Redstoneguy129/update.py': [Errno 2] No such file or directory
python3: can't open file '/Redstoneguy129/update.py': [Errno 2] No such file or directory
